Workbook
Name exercise_list: tbl_exercise_master[exercise]
Name rpe_list: tbl_rpe_list[rpe]

Sheet INBODY_LOG
A1: date | B1: weight_kg | C1: skeletal_muscle_kg | D1: body_fat_pct | E1: memo
A2: 46041 | B2: 52.5 | C2: 19.1 | D2: 31.7
A3: 46076 | B3: 53.2 | C3: 19.7 | D3: 30.5
A4: 46104 | B4: 52.4 | C4: 20.5 | D4: 27.2
A5: 46150 | B5: 51.4 | C5: 21.2 | D5: 23.5

Sheet WORKOUT_LOG
A1: date | B1: session | C1: exercise | D1: sets | E1: reps | F1: weight_kg | G1: rpe | H1: rpe_flag | I1: memo | J1: check_exercise
A2: 46076 | B2: =IF(C2="","",_xlfn.XLOOKUP(C2,tbl_exercise_master[exercise],tbl_exercise_master[session],"미등록")) | C2: Monster Glute Machine | D2: 1 | E2: 30 | F2: 10 | H2: =IF(G2="","No RPE","RPE") | J2: =IF(C2="","",IF(COUNTIF(EXERCISE_MASTER!$A:$A,C2)=0,"미등록","OK"))
A3: 46076 | B3: =IF(C3="","",_xlfn.XLOOKUP(C3,tbl_exercise_master[exercise],tbl_exercise_master[session],"미등록")) | C3: Monster Glute Machine | D3: 2 | E3: 20 | F3: 20 | H3: =IF(G3="","No RPE","RPE") | J3: =IF(C3="","",IF(COUNTIF(EXERCISE_MASTER!$A:$A,C3)=0,"미등록","OK"))
A4: 46076 | B4: =IF(C4="","",_xlfn.XLOOKUP(C4,tbl_exercise_master[exercise],tbl_exercise_master[session],"미등록")) | C4: Lying Leg Curl | D4: 1 | E4: 25 | F4: 7.5 | H4: =IF(G4="","No RPE","RPE") | J4: =IF(C4="","",IF(COUNTIF(EXERCISE_MASTER!$A:$A,C4)=0,"미등록","OK"))
A5: 46076 | B5: =IF(C5="","",_xlfn.XLOOKUP(C5,tbl_exercise_master[exercise],tbl_exercise_master[session],"미등록")) | C5: Lying Leg Curl | D5: 1 | E5: 15 | F5: 10 | H5: =IF(G5="","No RPE","RPE") | J5: =IF(C5="","",IF(COUNTIF(EXERCISE_MASTER!$A:$A,C5)=0,"미등록","OK"))
A6: 46076 | B6: =IF(C6="","",_xlfn.XLOOKUP(C6,tbl_exercise_master[exercise],tbl_exercise_master[session],"미등록")) | C6: Lying Leg Curl | D6: 1 | E6: 15 | F6: 12.5 | H6: =IF(G6="","No RPE","RPE") | J6: =IF(C6="","",IF(COUNTIF(EXERCISE_MASTER!$A:$A,C6)=0,"미등록","OK"))
A7: 46076 | B7: =IF(C7="","",_xlfn.XLOOKUP(C7,tbl_exercise_master[exercise],tbl_exercise_master[session],"미등록")) | C7: Dumbbell Sumo Squat | D7: 3 | E7: 15 | F7: 14 | H7: =IF(G7="","No RPE","RPE") | J7: =IF(C7="","",IF(COUNTIF(EXERCISE_MASTER!$A:$A,C7)=0,"미등록","OK"))
A8: 46077 | B8: =IF(C8="","",_xlfn.XLOOKUP(C8,tbl_exercise_master[exercise],tbl_exercise_master[session],"미등록")) | C8: Pec Deck Fly Machine | D8: 1 | E8: 15 | F8: 7.5 | H8: =IF(G8="","No RPE","RPE") | J8: =IF(C8="","",IF(COUNTIF(EXERCISE_MASTER!$A:$A,C8)=0,"미등록","OK"))
A9: 46077 | B9: =IF(C9="","",_xlfn.XLOOKUP(C9,tbl_exercise_master[exercise],tbl_exercise_master[session],"미등록")) | C9: Pec Deck Fly Machine | D9: 1 | E9: 12 | F9: 7.5 | H9: =IF(G9="","No RPE","RPE") | J9: =IF(C9="","",IF(COUNTIF(EXERCISE_MASTER!$A:$A,C9)=0,"미등록","OK"))
A10: 46077 | B10: =IF(C10="","",_xlfn.XLOOKUP(C10,tbl_exercise_master[exercise],tbl_exercise_master[session],"미등록")) | C10: Pec Deck Fly Machine | D10: 1 | E10: 10 | F10: 7.5 | H10: =IF(G10="","No RPE","RPE") | J10: =IF(C10="","",IF(COUNTIF(EXERCISE_MASTER!$A:$A,C10)=0,"미등록","OK"))
A11: 46077 | B11: =IF(C11="","",_xlfn.XLOOKUP(C11,tbl_exercise_master[exercise],tbl_exercise_master[session],"미등록")) | C11: Cable W Raise | D11: 1 | E11: 25 | F11: 1.5 | H11: =IF(G11="","No RPE","RPE") | J11: =IF(C11="","",IF(COUNTIF(EXERCISE_MASTER!$A:$A,C11)=0,"미등록","OK"))
A12: 46077 | B12: =IF(C12="","",_xlfn.XLOOKUP(C12,tbl_exercise_master[exercise],tbl_exercise_master[session],"미등록")) | C12: Cable W Raise | D12: 1 | E12: 15 | F12: 1.5 | H12: =IF(G12="","No RPE","RPE") | J12: =IF(C12="","",IF(COUNTIF(EXERCISE_MASTER!$A:$A,C12)=0,"미등록","OK"))
A13: 46077 | B13: =IF(C13="","",_xlfn.XLOOKUP(C13,tbl_exercise_master[exercise],tbl_exercise_master[session],"미등록")) | C13: Cable External Rotation | D13: 1 | E13: 10 | F13: 1.5 | H13: =IF(G13="","No RPE","RPE") | J13: =IF(C13="","",IF(COUNTIF(EXERCISE_MASTER!$A:$A,C13)=0,"미등록","OK"))
A14: 46077 | B14: =IF(C14="","",_xlfn.XLOOKUP(C14,tbl_exercise_master[exercise],tbl_exercise_master[session],"미등록")) | C14: Resistance Band External Rotation | D14: 2 | E14: 50 | F14: 0 | H14: =IF(G14="","No RPE","RPE") | I14: band light | J14: =IF(C14="","",IF(COUNTIF(EXERCISE_MASTER!$A:$A,C14)=0,"미등록","OK"))
A15: 46077 | B15: =IF(C15="","",_xlfn.XLOOKUP(C15,tbl_exercise_master[exercise],tbl_exercise_master[session],"미등록")) | C15: Resistance Band External Rotation | D15: 2 | E15: 60 | F15: 0 | H15: =IF(G15="","No RPE","RPE") | I15: band light | J15: =IF(C15="","",IF(COUNTIF(EXERCISE_MASTER!$A:$A,C15)=0,"미등록","OK"))
A16: 46077 | B16: =IF(C16="","",_xlfn.XLOOKUP(C16,tbl_exercise_master[exercise],tbl_exercise_master[session],"미등록")) | C16: Chest Press Machine | D16: 1 | E16: 15 | F16: 0 | H16: =IF(G16="","No RPE","RPE") | J16: =IF(C16="","",IF(COUNTIF(EXERCISE_MASTER!$A:$A,C16)=0,"미등록","OK"))
A17: 46077 | B17: =IF(C17="","",_xlfn.XLOOKUP(C17,tbl_exercise_master[exercise],tbl_exercise_master[session],"미등록")) | C17: Chest Press Machine | D17: 1 | E17: 15 | F17: 2.5 | H17: =IF(G17="","No RPE","RPE") | J17: =IF(C17="","",IF(COUNTIF(EXERCISE_MASTER!$A:$A,C17)=0,"미등록","OK"))
A18: 46077 | B18: =IF(C18="","",_xlfn.XLOOKUP(C18,tbl_exercise_master[exercise],tbl_exercise_master[session],"미등록")) | C18: Chest Press Machine | D18: 1 | E18: 10 | F18: 5 | H18: =IF(G18="","No RPE","RPE") | J18: =IF(C18="","",IF(COUNTIF(EXERCISE_MASTER!$A:$A,C18)=0,"미등록","OK"))
A19: 46077 | B19: =IF(C19="","",_xlfn.XLOOKUP(C19,tbl_exercise_master[exercise],tbl_exercise_master[session],"미등록")) | C19: Chest Press Machine | D19: 1 | E19: 6 | F19: 5 | H19: =IF(G19="","No RPE","RPE") | J19: =IF(C19="","",IF(COUNTIF(EXERCISE_MASTER!$A:$A,C19)=0,"미등록","OK"))
A20: 46077 | B20: =IF(C20="","",_xlfn.XLOOKUP(C20,tbl_exercise_master[exercise],tbl_exercise_master[session],"미등록")) | C20: Incline Push-Up | D20: 2 | E20: 8 | F20: 26.55 | H20: =IF(G20="","No RPE","RPE") | I20: low | J20: =IF(C20="","",IF(COUNTIF(EXERCISE_MASTER!$A:$A,C20)=0,"미등록","OK"))
A21: 46077 | B21: =IF(C21="","",_xlfn.XLOOKUP(C21,tbl_exercise_master[exercise],tbl_exercise_master[session],"미등록")) | C21: Dumbbell Lateral Raise | D21: 1 | E21: 50 | F21: 1 | H21: =IF(G21="","No RPE","RPE") | J21: =IF(C21="","",IF(COUNTIF(EXERCISE_MASTER!$A:$A,C21)=0,"미등록","OK"))
A22: 46077 | B22: =IF(C22="","",_xlfn.XLOOKUP(C22,tbl_exercise_master[exercise],tbl_exercise_master[session],"미등록")) | C22: Dumbbell Lateral Raise | D22: 2 | E22: 20 | F22: 2 | H22: =IF(G22="","No RPE","RPE") | J22: =IF(C22="","",IF(COUNTIF(EXERCISE_MASTER!$A:$A,C22)=0,"미등록","OK"))
A23: 46077 | B23: =IF(C23="","",_xlfn.XLOOKUP(C23,tbl_exercise_master[exercise],tbl_exercise_master[session],"미등록")) | C23: Shoulder Press Machine | D23: 2 | E23: 10 | F23: 5 | H23: =IF(G23="","No RPE","RPE") | J23: =IF(C23="","",IF(COUNTIF(EXERCISE_MASTER!$A:$A,C23)=0,"미등록","OK"))
A24: 46078 | B24: =IF(C24="","",_xlfn.XLOOKUP(C24,tbl_exercise_master[exercise],tbl_exercise_master[session],"미등록")) | C24: Straight-Arm Pulldown | D24: 1 | E24: 20 | F24: 7.5 | H24: =IF(G24="","No RPE","RPE") | J24: =IF(C24="","",IF(COUNTIF(EXERCISE_MASTER!$A:$A,C24)=0,"미등록","OK"))
A25: 46078 | B25: =IF(C25="","",_xlfn.XLOOKUP(C25,tbl_exercise_master[exercise],tbl_exercise_master[session],"미등록")) | C25: Straight-Arm Pulldown | D25: 1 | E25: 10 | F25: 10 | H25: =IF(G25="","No RPE","RPE") | J25: =IF(C25="","",IF(COUNTIF(EXERCISE_MASTER!$A:$A,C25)=0,"미등록","OK"))
A26: 46078 | B26: =IF(C26="","",_xlfn.XLOOKUP(C26,tbl_exercise_master[exercise],tbl_exercise_master[session],"미등록")) | C26: Straight-Arm Pulldown | D26: 1 | E26: 8 | F26: 10 | H26: =IF(G26="","No RPE","RPE") | J26: =IF(C26="","",IF(COUNTIF(EXERCISE_MASTER!$A:$A,C26)=0,"미등록","OK"))
A27: 46078 | B27: =IF(C27="","",_xlfn.XLOOKUP(C27,tbl_exercise_master[exercise],tbl_exercise_master[session],"미등록")) | C27: Seated Cable Row | D27: 1 | E27: 10 | F27: 20 | H27: =IF(G27="","No RPE","RPE") | J27: =IF(C27="","",IF(COUNTIF(EXERCISE_MASTER!$A:$A,C27)=0,"미등록","OK"))
A28: 46078 | B28: =IF(C28="","",_xlfn.XLOOKUP(C28,tbl_exercise_master[exercise],tbl_exercise_master[session],"미등록")) | C28: Seated Cable Row | D28: 3 | E28: 15 | F28: 15 | H28: =IF(G28="","No RPE","RPE") | J28: =IF(C28="","",IF(COUNTIF(EXERCISE_MASTER!$A:$A,C28)=0,"미등록","OK"))
A29: 46078 | B29: =IF(C29="","",_xlfn.XLOOKUP(C29,tbl_exercise_master[exercise],tbl_exercise_master[session],"미등록")) | C29: ISO-Lateral Row Machine | D29: 3 | E29: 20 | F29: 10 | H29: =IF(G29="","No RPE","RPE") | J29: =IF(C29="","",IF(COUNTIF(EXERCISE_MASTER!$A:$A,C29)=0,"미등록","OK"))
A30: 46078 | B30: =IF(C30="","",_xlfn.XLOOKUP(C30,tbl_exercise_master[exercise],tbl_exercise_master[session],"미등록")) | C30: Assist Pull-Up Machine | D30: 3 | E30: 15 | F30: 61 | H30: =IF(G30="","No RPE","RPE") | I30: assisted | J30: =IF(C30="","",IF(COUNTIF(EXERCISE_MASTER!$A:$A,C30)=0,"미등록","OK"))
A31: 46079 | B31: =IF(C31="","",_xlfn.XLOOKUP(C31,tbl_exercise_master[exercise],tbl_exercise_master[session],"미등록")) | C31: Hip Abduction Machine | D31: 1 | E31: 30 | F31: 40 | H31: =IF(G31="","No RPE","RPE") | J31: =IF(C31="","",IF(COUNTIF(EXERCISE_MASTER!$A:$A,C31)=0,"미등록","OK"))
A32: 46079 | B32: =IF(C32="","",_xlfn.XLOOKUP(C32,tbl_exercise_master[exercise],tbl_exercise_master[session],"미등록")) | C32: Hip Abduction Machine | D32: 1 | E32: 20 | F32: 47 | H32: =IF(G32="","No RPE","RPE") | J32: =IF(C32="","",IF(COUNTIF(EXERCISE_MASTER!$A:$A,C32)=0,"미등록","OK"))
A33: 46079 | B33: =IF(C33="","",_xlfn.XLOOKUP(C33,tbl_exercise_master[exercise],tbl_exercise_master[session],"미등록")) | C33: Hip Abduction Machine | D33: 1 | E33: 15 | F33: 54 | H33: =IF(G33="","No RPE","RPE") | J33: =IF(C33="","",IF(COUNTIF(EXERCISE_MASTER!$A:$A,C33)=0,"미등록","OK"))
A34: 46079 | B34: =IF(C34="","",_xlfn.XLOOKUP(C34,tbl_exercise_master[exercise],tbl_exercise_master[session],"미등록")) | C34: Leg Extension Machine | D34: 1 | E34: 20 | F34: 19 | H34: =IF(G34="","No RPE","RPE") | J34: =IF(C34="","",IF(COUNTIF(EXERCISE_MASTER!$A:$A,C34)=0,"미등록","OK"))
A35: 46079 | B35: =IF(C35="","",_xlfn.XLOOKUP(C35,tbl_exercise_master[exercise],tbl_exercise_master[session],"미등록")) | C35: Leg Extension Machine | D35: 1 | E35: 20 | F35: 22.5 | H35: =IF(G35="","No RPE","RPE") | J35: =IF(C35="","",IF(COUNTIF(EXERCISE_MASTER!$A:$A,C35)=0,"미등록","OK"))
A36: 46079 | B36: =IF(C36="","",_xlfn.XLOOKUP(C36,tbl_exercise_master[exercise],tbl_exercise_master[session],"미등록")) | C36: Leg Extension Machine | D36: 2 | E36: 15 | F36: 26 | H36: =IF(G36="","No RPE","RPE") | J36: =IF(C36="","",IF(COUNTIF(EXERCISE_MASTER!$A:$A,C36)=0,"미등록","OK"))
A37: 46079 | B37: =IF(C37="","",_xlfn.XLOOKUP(C37,tbl_exercise_master[exercise],tbl_exercise_master[session],"미등록")) | C37: Leg Press Machine | D37: 1 | E37: 15 | F37: 20 | H37: =IF(G37="","No RPE","RPE") | J37: =IF(C37="","",IF(COUNTIF(EXERCISE_MASTER!$A:$A,C37)=0,"미등록","OK"))
A38: 46079 | B38: =IF(C38="","",_xlfn.XLOOKUP(C38,tbl_exercise_master[exercise],tbl_exercise_master[session],"미등록")) | C38: Leg Press Machine | D38: 1 | E38: 20 | F38: 20 | H38: =IF(G38="","No RPE","RPE") | J38: =IF(C38="","",IF(COUNTIF(EXERCISE_MASTER!$A:$A,C38)=0,"미등록","OK"))
A39: 46079 | B39: =IF(C39="","",_xlfn.XLOOKUP(C39,tbl_exercise_master[exercise],tbl_exercise_master[session],"미등록")) | C39: Leg Press Machine | D39: 1 | E39: 10 | F39: 60 | H39: =IF(G39="","No RPE","RPE") | J39: =IF(C39="","",IF(COUNTIF(EXERCISE_MASTER!$A:$A,C39)=0,"미등록","OK"))
A40: 46079 | B40: =IF(C40="","",_xlfn.XLOOKUP(C40,tbl_exercise_master[exercise],tbl_exercise_master[session],"미등록")) | C40: Leg Press Machine | D40: 1 | E40: 15 | F40: 60 | H40: =IF(G40="","No RPE","RPE") | J40: =IF(C40="","",IF(COUNTIF(EXERCISE_MASTER!$A:$A,C40)=0,"미등록","OK"))
...

Sheet EXERCISE_MASTER
A1: exercise | B1: session | C1: equipment_type | D1: movement_pattern | E1: fatigue_type | F1: exercise_fatigue_factor | G1: active | H1: check_muscle_weight
A2: Overhead Press | B2: 밀기 | C2: Barbell | D2: Vertical press | E2: Upper compound | F2: 1.1 | G2: Y | H2: =IF(A2="","",IF(COUNTIF(MUSCLE_WEIGHT!$A:$A,A2)=0,"가중치 없음","OK"))
A3: Seated Dumbbell Shoulder Press | B3: 밀기 | C3: Dumbbell | D3: Vertical press | E3: Upper compound | F3: 1 | G3: Y | H3: =IF(A3="","",IF(COUNTIF(MUSCLE_WEIGHT!$A:$A,A3)=0,"가중치 없음","OK"))
A4: Shoulder Press Machine | B4: 밀기 | C4: Machine | D4: Vertical press | E4: Machine compound | F4: 0.9 | G4: Y | H4: =IF(A4="","",IF(COUNTIF(MUSCLE_WEIGHT!$A:$A,A4)=0,"가중치 없음","OK"))
A5: Dumbbell Bench Press | B5: 밀기 | C5: Dumbbell | D5: Horizontal press | E5: Upper compound | F5: 1 | G5: Y | H5: =IF(A5="","",IF(COUNTIF(MUSCLE_WEIGHT!$A:$A,A5)=0,"가중치 없음","OK"))
A6: Chest Press Machine | B6: 밀기 | C6: Machine | D6: Horizontal press | E6: Machine compound | F6: 0.9 | G6: Y | H6: =IF(A6="","",IF(COUNTIF(MUSCLE_WEIGHT!$A:$A,A6)=0,"가중치 없음","OK"))
A7: Incline Push-Up | B7: 밀기 | C7: Bodyweight | D7: Horizontal press | E7: Bodyweight | F7: 0.8 | G7: Y | H7: =IF(A7="","",IF(COUNTIF(MUSCLE_WEIGHT!$A:$A,A7)=0,"가중치 없음","OK"))
A8: Incline Dumbbell Press | B8: 밀기 | C8: Dumbbell | D8: Incline press | E8: Upper compound | F8: 1 | G8: Y | H8: =IF(A8="","",IF(COUNTIF(MUSCLE_WEIGHT!$A:$A,A8)=0,"가중치 없음","OK"))
A9: Incline Bench Press Machine | B9: 밀기 | C9: Machine | D9: Incline press | E9: Machine compound | F9: 0.9 | G9: Y | H9: =IF(A9="","",IF(COUNTIF(MUSCLE_WEIGHT!$A:$A,A9)=0,"가중치 없음","OK"))
A10: Incline Chest Press Machine | B10: 밀기 | C10: Machine | D10: Incline press | E10: Machine compound | F10: 0.9 | G10: Y | H10: =IF(A10="","",IF(COUNTIF(MUSCLE_WEIGHT!$A:$A,A10)=0,"가중치 없음","OK"))
A11: Assist Dips Machine | B11: 밀기 | C11: Assisted Machine | D11: Vertical push | E11: Assisted compound | F11: 0.9 | G11: Y | H11: =IF(A11="","",IF(COUNTIF(MUSCLE_WEIGHT!$A:$A,A11)=0,"가중치 없음","OK"))
A12: Pec Deck Fly Machine | B12: 밀기 | C12: Machine | D12: Chest fly | E12: Isolation | F12: 0.6 | G12: Y | H12: =IF(A12="","",IF(COUNTIF(MUSCLE_WEIGHT!$A:$A,A12)=0,"가중치 없음","OK"))
A13: Dumbbell Front Raise | B13: 밀기 | C13: Dumbbell | D13: Shoulder flexion | E13: Isolation | F13: 0.6 | G13: Y | H13: =IF(A13="","",IF(COUNTIF(MUSCLE_WEIGHT!$A:$A,A13)=0,"가중치 없음","OK"))
... A20: EZ Bar Lying Triceps Extension | B20: 밀기 | C20: EZ Bar | D20: Elbow extension | E20: Isolation | F20: 0.7 | G20: Y | H20: =IF(A20="","",IF(COUNTIF(MUSCLE_WEIGHT!$A:$A,A20)=0,"가중치 없음","OK"))
A21: Wide Press Machine | B21: 밀기 | C21: Machine | D21: Horizontal press | E21: Machine compound | F21: 0.9 | G21: Y | H21: OK
A22: Lat Pulldown | B22: 당기기 | C22: Cable | D22: Vertical pull | E22: Upper compound | F22: 0.9 | G22: Y | H22: =IF(A22="","",IF(COUNTIF(MUSCLE_WEIGHT!$A:$A,A22)=0,"가중치 없음","OK"))
A23: Parallel Grip Lat Pulldown | B23: 당기기 | C23: Cable | D23: Vertical pull | E23: Upper compound | F23: 0.9 | G23: Y | H23: =IF(A23="","",IF(COUNTIF(MUSCLE_WEIGHT!$A:$A,A23)=0,"가중치 없음","OK"))
A24: A-Grip Lat Pulldown | B24: 당기기 | C24: Cable | D24: Vertical pull | E24: Upper compound | F24: 0.9 | G24: Y | H24: =IF(A24="","",IF(COUNTIF(MUSCLE_WEIGHT!$A:$A,A24)=0,"가중치 없음","OK"))
A25: MAG Grip Lat Pulldown | B25: 당기기 | C25: Cable | D25: Vertical pull | E25: Upper compound | F25: 0.9 | G25: Y | H25: =IF(A25="","",IF(COUNTIF(MUSCLE_WEIGHT!$A:$A,A25)=0,"가중치 없음","OK"))
A26: Lateral Wide Pulldown | B26: 당기기 | C26: Machine | D26: Vertical pull | E26: Machine compound | F26: 0.9 | G26: Y | H26: =IF(A26="","",IF(COUNTIF(MUSCLE_WEIGHT!$A:$A,A26)=0,"가중치 없음","OK"))
A27: Front Pulldown Machine | B27: 당기기 | C27: Machine | D27: Vertical pull | E27: Machine compound | F27: 0.9 | G27: Y | H27: =IF(A27="","",IF(COUNTIF(MUSCLE_WEIGHT!$A:$A,A27)=0,"가중치 없음","OK"))
A28: One-Arm Front Pulldown Machine | B28: 당기기 | C28: Machine | D28: Vertical pull | E28: Unilateral upper | F28: 0.85 | G28: Y | H28: =IF(A28="","",IF(COUNTIF(MUSCLE_WEIGHT!$A:$A,A28)=0,"가중치 없음","OK"))
A29: Assist Pull-Up Machine | B29: 당기기 | C29: Assisted Machine | D29: Vertical pull | E29: Assisted compound | F29: 0.9 | G29: Y | H29: =IF(A29="","",IF(COUNTIF(MUSCLE_WEIGHT!$A:$A,A29)=0,"가중치 없음","OK"))
A30: One-Arm Dumbbell Row | B30: 당기기 | C30: Dumbbell | D30: Horizontal pull | E30: Upper compound | F30: 1 | G30: Y | H30: =IF(A30="","",IF(COUNTIF(MUSCLE_WEIGHT!$A:$A,A30)=0,"가중치 없음","OK"))
A31: Chest-Supported T-Bar Row | B31: 당기기 | C31: Machine | D31: Horizontal pull | E31: Upper compound | F31: 1 | G31: Y | H31: =IF(A31="","",IF(COUNTIF(MUSCLE_WEIGHT!$A:$A,A31)=0,"가중치 없음","OK"))
A32: ISO-Lateral Row Machine | B32: 당기기 | C32: Machine | D32: Horizontal pull | E32: Machine compound | F32: 0.9 | G32: Y | H32: =IF(A32="","",IF(COUNTIF(MUSCLE_WEIGHT!$A:$A,A32)=0,"가중치 없음","OK"))
A33: Seated Row Machine | B33: 당기기 | C33: Machine | D33: Horizontal pull | E33: Machine compound | F33: 0.9 | G33: Y | H33: =IF(A33="","",IF(COUNTIF(MUSCLE_WEIGHT!$A:$A,A33)=0,"가중치 없음","OK"))
... A71: Seated Leg Curl | B71: 하체 | C71: Machine | D71: Knee flexion | E71: Isolation | F71: 0.7 | G71: Y | H71: =IF(A71="","",IF(COUNTIF(MUSCLE_WEIGHT!$A:$A,A71)=0,"가중치 없음","OK"))

Sheet MUSCLE_WEIGHT
A1: exercise | B1: muscle_group | C1: ratio | D1: ratio_sum
A2: Overhead Press | B2: Shoulders | C2: 0.6 | D2: =SUMIF($A:$A,A2,$C:$C)
A3: Overhead Press | B3: Triceps | C3: 0.25 | D3: =SUMIF($A:$A,A3,$C:$C)
A4: Overhead Press | B4: Chest | C4: 0.15 | D4: =SUMIF($A:$A,A4,$C:$C)
A5: Seated Dumbbell Shoulder Press | B5: Shoulders | C5: 0.65 | D5: =SUMIF($A:$A,A5,$C:$C)
A6: Seated Dumbbell Shoulder Press | B6: Triceps | C6: 0.25 | D6: =SUMIF($A:$A,A6,$C:$C)
A7: Seated Dumbbell Shoulder Press | B7: Chest | C7: 0.1 | D7: =SUMIF($A:$A,A7,$C:$C)
A8: Shoulder Press Machine | B8: Shoulders | C8: 0.65 | D8: =SUMIF($A:$A,A8,$C:$C)
A9: Shoulder Press Machine | B9: Triceps | C9: 0.25 | D9: =SUMIF($A:$A,A9,$C:$C)
A10: Shoulder Press Machine | B10: Chest | C10: 0.1 | D10: =SUMIF($A:$A,A10,$C:$C)
A11: Dumbbell Bench Press | B11: Chest | C11: 0.6 | D11: =SUMIF($A:$A,A11,$C:$C)
A12: Dumbbell Bench Press | B12: Shoulders | C12: 0.2 | D12: =SUMIF($A:$A,A12,$C:$C)
A13: Dumbbell Bench Press | B13: Triceps | C13: 0.2 | D13: =SUMIF($A:$A,A13,$C:$C)
... A188: Seated Leg Curl | B188: Hamstrings | C188: 1 | D188: =SUMIF($A:$A,A188,$C:$C)

Sheet RPE_SCALE
A1: rpe | B1: stimulus_factor | C1: fatigue_factor | D1: description
A2: 1 | B2: 0.1 | C2: 0.05 | D2: 거의 노력 없음
A3: 2 | B3: 0.2 | C3: 0.1 | D3: 매우 쉬움
A4: 3 | B4: 0.35 | C4: 0.2 | D4: 쉬움
A5: 4 | B5: 0.5 | C5: 0.35 | D5: 약간 쉬움
A6: 5 | B6: 0.6 | C6: 0.45 | D6: 보통
A7: 6 | B7: 0.7 | C7: 0.6 | D7: 약 4회 이상 더 가능
A8: 7 | B8: 0.85 | C8: 0.8 | D8: 약 3회 더 가능
A9: 8 | B9: 1 | C9: 1 | D9: 약 2회 더 가능
A10: 9 | B10: 1.1 | C10: 1.3 | D10: 약 1회 더 가능
A11: 10 | B11: 1.15 | C11: 1.7 | D11: 더 이상 반복 불가

Sheet SETTINGS
A1: key | B1: value | C1: memo

Sheet ETC
A1: Push-Up 부하계수 | B1: 높은 박스 또는 벤치 | C1: 체중 * 0.4
A2: Push-Up 부하계수 | B2: 낮은 벤치 | C2: 체중 * 0.5
A3: Push-Up 부하계수 | B3: 바닥 | C3: 체중 * 0.6
A4: Push-Up 부하계수 | B4: 디클라인 | C4: 체중 * 0.7

Sheet SUMMARY_INBODY
A1: date | B1: weight_kg | C1: skeletal_muscle_kg | D1: body_fat_pct | E1: memo | F1: weight_diff | G1: skeletal_muscle_diff | H1: body_fat_pct_diff | I1: weight_change_text | J1: muscle_change_text | K1: fat_change_text | L1: body_composition_type
A2: 46041 | B2: 52.5 | C2: 19.1 | D2: 31.7 | I2: 이전 측정값 없음 | J2: 이전 측정값 없음 | K2: 이전 측정값 없음 | L2: Baseline
A3: 46076 | B3: 53.2 | C3: 19.7 | D3: 30.5 | F3: 0.7 | G3: 0.6 | H3: -1.2 | I3: 체중이 전보다 0.7kg 증가했어요 | J3: 골격근량이 전보다 0.6kg 증가했어요 | K3: 체지방률이 전보다 1.2%p 감소했어요 | L3: Lean mass up
A4: 46104 | B4: 52.4 | C4: 20.5 | D4: 27.2 | F4: -0.8 | G4: 0.8 | H4: -3.3 | I4: 체중이 전보다 0.8kg 감소했어요 | J4: 골격근량이 전보다 0.8kg 증가했어요 | K4: 체지방률이 전보다 3.3%p 감소했어요 | L4: Recomposition
A5: 46150 | B5: 51.4 | C5: 21.2 | D5: 23.5 | F5: -1 | G5: 0.7 | H5: -3.7 | I5: 체중이 전보다 1.0kg 감소했어요 | J5: 골격근량이 전보다 0.7kg 증가했어요 | K5: 체지방률이 전보다 3.7%p 감소했어요 | L5: Recomposition

Sheet CALC_WORKOUT
A1: date | B1: week_start | C1: session | D1: exercise | E1: equipment_type | F1: movement_pattern | G1: fatigue_type | H1: sets | I1: reps | J1: weight_kg | K1: rpe | L1: rpe_available | M1: raw_volume | N1: muscle_group | O1: ratio | P1: muscle_volume | Q1: stimulus_factor | R1: stimulus_score | S1: fatigue_factor | T1: exercise_fatigue_factor | U1: fatigue_load
A2: 46076 | B2: 46076 | C2: nan | D2: Dumbbell Sumo Squat | E2: Dumbbell | F2: Squat | G2: Dumbbell lower compound | H2: 3 | I2: 15 | J2: 14 | L2: N | M2: 630 | N2: Hamstrings | O2: 0.1 | P2: 63 | T2: 1
A3: 46076 | B3: 46076 | C3: nan | D3: Dumbbell Sumo Squat | E3: Dumbbell | F3: Squat | G3: Dumbbell lower compound | H3: 3 | I3: 15 | J3: 14 | L3: N | M3: 630 | N3: Hips | O3: 0.45 | P3: 283.5 | T3: 1
A4: 46076 | B4: 46076 | C4: nan | D4: Dumbbell Sumo Squat | E4: Dumbbell | F4: Squat | G4: Dumbbell lower compound | H4: 3 | I4: 15 | J4: 14 | L4: N | M4: 630 | N4: Lower Back | O4: 0.1 | P4: 63 | T4: 1
A5: 46076 | B5: 46076 | C5: nan | D5: Dumbbell Sumo Squat | E5: Dumbbell | F5: Squat | G5: Dumbbell lower compound | H5: 3 | I5: 15 | J5: 14 | L5: N | M5: 630 | N5: Quadriceps | O5: 0.35 | P5: 220.5 | T5: 1
A6: 46076 | B6: 46076 | C6: nan | D6: Lying Leg Curl | E6: Machine | F6: Knee flexion | G6: Isolation | H6: 1 | I6: 25 | J6: 7.5 | L6: N | M6: 187.5 | N6: Hamstrings | O6: 1 | P6: 187.5 | T6: 0.7
A7: 46076 | B7: 46076 | C7: nan | D7: Lying Leg Curl | E7: Machine | F7: Knee flexion | G7: Isolation | H7: 1 | I7: 15 | J7: 10 | L7: N | M7: 150 | N7: Hamstrings | O7: 1 | P7: 150 | T7: 0.7
A8: 46076 | B8: 46076 | C8: nan | D8: Lying Leg Curl | E8: Machine | F8: Knee flexion | G8: Isolation | H8: 1 | I8: 15 | J8: 12.5 | L8: N | M8: 187.5 | N8: Hamstrings | O8: 1 | P8: 187.5 | T8: 0.7
A9: 46076 | B9: 46076 | C9: nan | D9: Monster Glute Machine | E9: Machine | F9: Hip extension | G9: Glute machine | H9: 1 | I9: 30 | J9: 10 | L9: N | M9: 300 | N9: Hamstrings | O9: 0.1 | P9: 30 | T9: 0.9
A10: 46076 | B10: 46076 | C10: nan | D10: Monster Glute Machine | E10: Machine | F10: Hip extension | G10: Glute machine | H10: 2 | I10: 20 | J10: 20 | L10: N | M10: 800 | N10: Hamstrings | O10: 0.1 | P10: 80 | T10: 0.9
A11: 46076 | B11: 46076 | C11: nan | D11: Monster Glute Machine | E11: Machine | F11: Hip extension | G11: Glute machine | H11: 1 | I11: 30 | J11: 10 | L11: N | M11: 300 | N11: Hips | O11: 0.85 | P11: 255 | T11: 0.9
A12: 46076 | B12: 46076 | C12: nan | D12: Monster Glute Machine | E12: Machine | F12: Hip extension | G12: Glute machine | H12: 2 | I12: 20 | J12: 20 | L12: N | M12: 800 | N12: Hips | O12: 0.85 | P12: 680 | T12: 0.9
A13: 46076 | B13: 46076 | C13: nan | D13: Monster Glute Machine | E13: Machine | F13: Hip extension | G13: Glute machine | H13: 1 | I13: 30 | J13: 10 | L13: N | M13: 300 | N13: Lower Back | O13: 0.05 | P13: 15 | T13: 0.9
... A1295: 46136 | B1295: 46132 | C1295: nan | D1295: Rear Deltoid Fly Machine | E1295: Machine | F1295: Rear delt fly | G1295: Isolation | H1295: 1 | I1295: 17 | J1295: 12 | L1295: N | M1295: 204 | N1295: Upper Back | O1295: 0.3 | P1295: 61.2 | T1295: 0.6
A1296: 46137 | B1296: 46132 | C1296: nan | D1296: EZ Bar Curl | E1296: EZ Bar | F1296: Elbow flexion | G1296: Isolation | H1296: 3 | I1296: 15 | J1296: 10 | K1296: 10 | L1296: Y | M1296: 450 | N1296: Biceps | O1296: 1 | P1296: 450 | Q1296: 1.15 | R1296: 517.5 | S1296: 1.7 | T1296: 0.6 | U1296: 459
A1297: 46137 | B1297: 46132 | C1297: nan | D1297: ISO-Lateral Row Machine | E1297: Machine | F1297: Horizontal pull | G1297: Machine compound | H1297: 4 | I1297: 15 | J1297: 17.5 | K1297: 7 | L1297: Y | M1297: 1050 | N1297: Biceps | O1297: 0.2 | P1297: 210 | Q1297: 0.85 | R1297: 178.5 | S1297: 0.8 | T1297: 0.9 | U1297: 756
A1298: 46137 | B1298: 46132 | C1298: nan | D1298: ISO-Lateral Row Machine | E1298: Machine | F1298: Horizontal pull | G1298: Machine compound | H1298: 4 | I1298: 15 | J1298: 17.5 | K1298: 7 | L1298: Y | M1298: 1050 | N1298: Shoulders | O1298: 0.1 | P1298: 105 | Q1298: 0.85 | R1298: 89.25 | S1298: 0.8 | T1298: 0.9 | U1298: 756
A1299: 46137 | B1299: 46132 | C1299: nan | D1299: ISO-Lateral Row Machine | E1299: Machine | F1299: Horizontal pull | G1299: Machine compound | H1299: 4 | I1299: 15 | J1299: 17.5 | K1299: 7 | L1299: Y | M1299: 1050 | N1299: Upper Back | O1299: 0.7 | P1299: 735 | Q1299: 0.85 | R1299: 624.75 | S1299: 0.8 | T1299: 0.9 | U1299: 756
A1300: 46137 | B1300: 46132 | C1300: nan | D1300: Lateral Wide Pulldown | E1300: Machine | F1300: Vertical pull | G1300: Machine compound | H1300: 4 | I1300: 15 | J1300: 15 | K1300: 8 | L1300: Y | M1300: 900 | N1300: Biceps | O1300: 0.2 | P1300: 180 | Q1300: 1 | R1300: 180 | S1300: 1 | T1300: 0.9 | U1300: 810
A1301: 46137 | B1301: 46132 | C1301: nan | D1301: Lateral Wide Pulldown | E1301: Machine | F1301: Vertical pull | G1301: Machine compound | H1301: 4 | I1301: 15 | J1301: 15 | K1301: 8 | L1301: Y | M1301: 900 | N1301: Shoulders | O1301: 0.05 | P1301: 45 | Q1301: 1 | R1301: 45 | S1301: 1 | T1301: 0.9 | U1301: 810
A1302: 46137 | B1302: 46132 | C1302: nan | D1302: Lateral Wide Pulldown | E1302: Machine | F1302: Vertical pull | G1302: Machine compound | H1302: 4 | I1302: 15 | J1302: 15 | K1302: 8 | L1302: Y | M1302: 900 | N1302: Upper Back | O1302: 0.75 | P1302: 675 | Q1302: 1 | R1302: 675 | S1302: 1 | T1302: 0.9 | U1302: 810
A1303: 46137 | B1303: 46132 | C1303: nan | D1303: MAG Grip Lat Pulldown | E1303: Cable | F1303: Vertical pull | G1303: Upper compound | H1303: 1 | I1303: 15 | J1303: 25 | K1303: 10 | L1303: Y | M1303: 375 | N1303: Biceps | O1303: 0.25 | P1303: 93.75 | Q1303: 1.15 | R1303: 107.8125 | S1303: 1.7 | T1303: 0.9 | U1303: 573.75
A1304: 46137 | B1304: 46132 | C1304: nan | D1304: MAG Grip Lat Pulldown | E1304: Cable | F1304: Vertical pull | G1304: Upper compound | H1304: 1 | I1304: 12 | J1304: 25 | K1304: 10 | L1304: Y | M1304: 300 | N1304: Biceps | O1304: 0.25 | P1304: 75 | Q1304: 1.15 | R1304: 86.25 | S1304: 1.7 | T1304: 0.9 | U1304: 459
A1305: 46137 | B1305: 46132 | C1305: nan | D1305: MAG Grip Lat Pulldown | E1305: Cable | F1305: Vertical pull | G1305: Upper compound | H1305: 1 | I1305: 10 | J1305: 25 | K1305: 10 | L1305: Y | M1305: 250 | N1305: Biceps | O1305: 0.25 | P1305: 62.5 | Q1305: 1.15 | R1305: 71.875 | S1305: 1.7 | T1305: 0.9 | U1305: 382.5
A1306: 46137 | B1306: 46132 | C1306: nan | D1306: MAG Grip Lat Pulldown | E1306: Cable | F1306: Vertical pull | G1306: Upper compound | H1306: 1 | I1306: 15 | J1306: 25 | K1306: 10 | L1306: Y | M1306: 375 | N1306: Shoulders | O1306: 0.05 | P1306: 18.75 | Q1306: 1.15 | R1306: 21.5625 | S1306: 1.7 | T1306: 0.9 | U1306: 573.75
A1307: 46137 | B1307: 46132 | C1307: nan | D1307: MAG Grip Lat Pulldown | E1307: Cable | F1307: Vertical pull | G1307: Upper compound | H1307: 1 | I1307: 12 | J1307: 25 | K1307: 10 | L1307: Y | M1307: 300 | N1307: Shoulders | O1307: 0.05 | P1307: 15 | Q1307: 1.15 | R1307: 17.25 | S1307: 1.7 | T1307: 0.9 | U1307: 459
... A1639: 46150 | B1639: 46146 | C1639: nan | D1639: Seated Row Machine | E1639: Machine | F1639: Horizontal pull | G1639: Machine compound | H1639: 1 | I1639: 15 | J1639: 19 | K1639: 4 | L1639: Y | M1639: 285 | N1639: Upper Back | O1639: 0.7 | P1639: 199.5 | Q1639: 0.5 | R1639: 99.75 | S1639: 0.35 | T1639: 0.9 | U1639: 89.775

Sheet SUMMARY_WORKOUT_DAILY
A1: date | B1: session | C1: total_raw_volume | D1: total_muscle_volume | E1: total_stimulus_score | F1: total_fatigue_load
A2: 46076 | B2: nan | C2: 6345 | D2: 2255 | E2: 0 | F2: 0
A3: 46077 | B3: nan | C3: 2761.9 | D3: 1124.8 | E3: 0 | F3: 0
A4: 46078 | B4: nan | C4: 13320 | D4: 4550 | E4: 0 | F4: 0
A5: 46079 | B5: nan | C5: 18310 | D5: 7260 | E5: 0 | F5: 0
A6: 46081 | B6: nan | C6: 1995 | D6: 795 | E6: 0 | F6: 0
A7: 46082 | B7: nan | C7: 8099 | D7: 2677 | E7: 0 | F7: 0
A8: 46083 | B8: nan | C8: 11342.5 | D8: 5332.5 | E8: 0 | F8: 0
A9: 46084 | B9: nan | C9: 2524.5 | D9: 1006.5 | E9: 0 | F9: 0
A10: 46086 | B10: nan | C10: 14600 | D10: 4975 | E10: 0 | F10: 0
A11: 46087 | B11: nan | C11: 27520 | D11: 8950 | E11: 0 | F11: 0
A12: 46088 | B12: nan | C12: 3055.5 | D12: 1213.5 | E12: 0 | F12: 0
A13: 46089 | B13: nan | C13: 7847.5 | D13: 3077.5 | E13: 0 | F13: 0
... A64: 46150 | B64: nan | C64: 17797.5 | D64: 5932.5 | E64: 5547.375 | F64: 17794.688

Sheet SUMMARY_WORKOUT_WEEKLY
A1: week_start | B1: session | C1: total_raw_volume | D1: total_muscle_volume | E1: total_stimulus_score | F1: total_fatigue_load
A2: 46076 | B2: nan | C2: 50830.9 | D2: 18661.8 | E2: 0 | F2: 0
A3: 46083 | B3: nan | C3: 66890 | D3: 24555 | E3: 0 | F3: 0
A4: 46090 | B4: nan | C4: 47650.5 | D4: 17615.5 | E4: 0 | F4: 0
A5: 46097 | B5: nan | C5: 59845.75 | D5: 22237.75 | E5: 0 | F5: 0
A6: 46104 | B6: nan | C6: 95677.5 | D6: 33709 | E6: 0 | F6: 0
A7: 46104 | B7: 하체 | C7: 1152 | D7: 288 | E7: 0 | F7: 0
A8: 46111 | B8: nan | C8: 72153.5 | D8: 26943.5 | E8: 0 | F8: 0
A9: 46118 | B9: nan | C9: 103653 | D9: 35240 | E9: 0 | F9: 0
A10: 46125 | B10: nan | C10: 98981.5 | D10: 35762 | E10: 0 | F10: 0
A11: 46132 | B11: nan | C11: 99436 | D11: 35890.5 | E11: 18116.5 | F11: 52264.35
A12: 46139 | B12: nan | C12: 98466 | D12: 31073.5 | E12: 27555.325 | F12: 88895.995
A13: 46146 | B13: nan | C13: 93369.5 | D13: 33377.5 | E13: 30701.675 | F13: 79641.148

Sheet SUMMARY_MUSCLE_WEEKLY
A1: week_start | B1: muscle_group | C1: muscle_volume | D1: stimulus_score
A2: 46076 | B2: Biceps | C2: 1482.85 | D2: 0
A3: 46076 | B3: Chest | C3: 1022.89 | D3: 0
A4: 46076 | B4: Hamstrings | C4: 946 | D4: 0
A5: 46076 | B5: Hips | C5: 4777.5 | D5: 0
A6: 46076 | B6: Lower Back | C6: 565.4 | D6: 0
A7: 46076 | B7: Quadriceps | C7: 3240.5 | D7: 0
A8: 46076 | B8: Shoulders | C8: 1227.7 | D8: 0
A9: 46076 | B9: Triceps | C9: 421.46 | D9: 0
A10: 46076 | B10: Upper Back | C10: 4977.5 | D10: 0
A11: 46083 | B11: Biceps | C11: 1828.75 | D11: 0
A12: 46083 | B12: Chest | C12: 1023 | D12: 0
A13: 46083 | B13: Hamstrings | C13: 1867 | D13: 0
... A100: 46146 | B100: Upper Back | C100: 7518.1 | D100: 7266.4712

Sheet VALIDATION
A1: check_type | B1: exercise | C1: status
A2: All validation checks | B2: - | C2: OK
